{
  "timestamp": "2025-09-09T16:43:37.855177",
  "phase": "Phase 4 Comprehensive Validation",
  "status": "failed",
  "tests": {
    "Quality Metrics Validation": {
      "script": "phase4_quality_metrics_validation.py",
      "description": "Test Precision, MRR, NDCG calculation accuracy",
      "result": {
        "status": "failed",
        "return_code": 1,
        "stdout": "",
        "stderr": "Traceback (most recent call last):\n  File \"D:\\codex\\datamaster\\backend-ops\\data-vault-obsidian\\scripts\\phase4_quality_metrics_validation.py\", line 24, in <module>\n    from search.semantic_search_service import SemanticSearchService\nModuleNotFoundError: No module named 'search.semantic_search_service'\n\nDuring handling of the above exception, another exception occurred:\n\nTraceback (most recent call last):\n  File \"D:\\codex\\datamaster\\backend-ops\\data-vault-obsidian\\scripts\\phase4_quality_metrics_validation.py\", line 31, in <module>\n    print(f\"\\u274c Import error: {e}\")\n    ~~~~~^^^^^^^^^^^^^^^^^^^^^^^^^\n  File \"C:\\Users\\mathe\\AppData\\Local\\Programs\\Python\\Python313\\Lib\\encodings\\cp1252.py\", line 19, in encode\n    return codecs.charmap_encode(input,self.errors,encoding_table)[0]\n           ~~~~~~~~~~~~~~~~~~~~~^^^^^^^^^^^^^^^^^^^^^^^^^^^^^^^^^^\nUnicodeEncodeError: 'charmap' codec can't encode character '\\u274c' in position 0: character maps to <undefined>\n"
      }
    },
    "User Feedback Collection Validation": {
      "script": "phase4_feedback_validation.py",
      "description": "Test interactive feedback system and learning mechanisms",
      "result": {
        "status": "failed",
        "return_code": 1,
        "stdout": "",
        "stderr": "Traceback (most recent call last):\n  File \"D:\\codex\\datamaster\\backend-ops\\data-vault-obsidian\\scripts\\phase4_feedback_validation.py\", line 24, in <module>\n    from search.semantic_search_service import SemanticSearchService\nModuleNotFoundError: No module named 'search.semantic_search_service'\n\nDuring handling of the above exception, another exception occurred:\n\nTraceback (most recent call last):\n  File \"D:\\codex\\datamaster\\backend-ops\\data-vault-obsidian\\scripts\\phase4_feedback_validation.py\", line 31, in <module>\n    print(f\"\\u274c Import error: {e}\")\n    ~~~~~^^^^^^^^^^^^^^^^^^^^^^^^^\n  File \"C:\\Users\\mathe\\AppData\\Local\\Programs\\Python\\Python313\\Lib\\encodings\\cp1252.py\", line 19, in encode\n    return codecs.charmap_encode(input,self.errors,encoding_table)[0]\n           ~~~~~~~~~~~~~~~~~~~~~^^^^^^^^^^^^^^^^^^^^^^^^^^^^^^^^^^\nUnicodeEncodeError: 'charmap' codec can't encode character '\\u274c' in position 0: character maps to <undefined>\n"
      }
    },
    "Response Quality Evaluation Validation": {
      "script": "phase4_response_evaluation_validation.py",
      "description": "Test relevance scoring and response assessment",
      "result": {
        "status": "failed",
        "return_code": 1,
        "stdout": "",
        "stderr": "Traceback (most recent call last):\n  File \"D:\\codex\\datamaster\\backend-ops\\data-vault-obsidian\\scripts\\phase4_response_evaluation_validation.py\", line 25, in <module>\n    from search.semantic_search_service import SemanticSearchService\nModuleNotFoundError: No module named 'search.semantic_search_service'\n\nDuring handling of the above exception, another exception occurred:\n\nTraceback (most recent call last):\n  File \"D:\\codex\\datamaster\\backend-ops\\data-vault-obsidian\\scripts\\phase4_response_evaluation_validation.py\", line 32, in <module>\n    print(f\"\\u274c Import error: {e}\")\n    ~~~~~^^^^^^^^^^^^^^^^^^^^^^^^^\n  File \"C:\\Users\\mathe\\AppData\\Local\\Programs\\Python\\Python313\\Lib\\encodings\\cp1252.py\", line 19, in encode\n    return codecs.charmap_encode(input,self.errors,encoding_table)[0]\n           ~~~~~~~~~~~~~~~~~~~~~^^^^^^^^^^^^^^^^^^^^^^^^^^^^^^^^^^\nUnicodeEncodeError: 'charmap' codec can't encode character '\\u274c' in position 0: character maps to <undefined>\n"
      }
    },
    "Performance Monitoring Validation": {
      "script": "phase4_monitoring_validation.py",
      "description": "Test real-time metrics and system health monitoring",
      "result": {
        "status": "failed",
        "return_code": 1,
        "stdout": "",
        "stderr": "Traceback (most recent call last):\n  File \"D:\\codex\\datamaster\\backend-ops\\data-vault-obsidian\\scripts\\phase4_monitoring_validation.py\", line 27, in <module>\n    from search.semantic_search_service import SemanticSearchService\nModuleNotFoundError: No module named 'search.semantic_search_service'\n\nDuring handling of the above exception, another exception occurred:\n\nTraceback (most recent call last):\n  File \"D:\\codex\\datamaster\\backend-ops\\data-vault-obsidian\\scripts\\phase4_monitoring_validation.py\", line 34, in <module>\n    print(f\"\\u274c Import error: {e}\")\n    ~~~~~^^^^^^^^^^^^^^^^^^^^^^^^^\n  File \"C:\\Users\\mathe\\AppData\\Local\\Programs\\Python\\Python313\\Lib\\encodings\\cp1252.py\", line 19, in encode\n    return codecs.charmap_encode(input,self.errors,encoding_table)[0]\n           ~~~~~~~~~~~~~~~~~~~~~^^^^^^^^^^^^^^^^^^^^^^^^^^^^^^^^^^\nUnicodeEncodeError: 'charmap' codec can't encode character '\\u274c' in position 0: character maps to <undefined>\n"
      }
    }
  },
  "summary": {
    "overall_success": false,
    "total_tests": 4,
    "successful_tests": 0,
    "failed_tests": 4,
    "success_rate": 0.0
  }
}